Workbook

Sheet Sheet1
A1: No. | B1: company | C1: 業種 | D1: share | E1: Op_2021 | F1: Op_2022 | G1: Op_2023 | H1: Op_2024 | I1: Op_2025 | J1: Op_2026 | K1: Op_2027 | L1: FCF_2021 | M1: FCF_2022 | N1: FCF_2023 | O1: FCF_2024 | P1: FCF_2025 | Q1: ROE_2021 | R1: ROE_2022 | S1: ROE_2023 | T1: ROE_2024 | U1: ROE_2025 | V1: ticker | W1: PER | X1: PBR | Y1: 市場区分
A2: 1 | B2: =_xlfn.XLOOKUP('Sheet1 (4)'!AB8,'Sheet1 (3)'!B:B,'Sheet1 (3)'!C:C,"",0) -> Ａｎｄ Ｄｏホールディングス | C2: =_xlfn.XLOOKUP('Sheet1 (4)'!AB8,'Sheet1 (3)'!B:B,'Sheet1 (3)'!F:F,"",0) -> 不動産業 | D2: =ROUND('Sheet1 (4)'!E8/100000000,2) -> 0.2 | E2: =ROUND('Sheet1 (4)'!F8/100,2) -> 25.89 | F2: =ROUND('Sheet1 (4)'!G8/100,2) -> 28.72 | G2: =ROUND('Sheet1 (4)'!H8/100,2) -> 31.77 | H2: =ROUND('Sheet1 (4)'!I8/100,2) -> 35.88 | I2: =ROUND('Sheet1 (4)'!J8/100,2) -> 26.21 | J2: =ROUND('Sheet1 (4)'!K8/100,2) -> #VALUE! | K2: =ROUND('Sheet1 (4)'!L8/100,2) -> #VALUE! | L2: =ROUND(('Sheet1 (4)'!M8+'Sheet1 (4)'!R8)/100,2) -> -25.93 | M2: =ROUND(('Sheet1 (4)'!N8+'Sheet1 (4)'!S8)/100,2) -> -88.96 | N2: =ROUND(('Sheet1 (4)'!O8+'Sheet1 (4)'!T8)/100,2) -> -191.21 | O2: =ROUND(('Sheet1 (4)'!P8+'Sheet1 (4)'!U8)/100,2) -> 61.31 | P2: =ROUND(('Sheet1 (4)'!Q8+'Sheet1 (4)'!V8)/100,2) -> 67.87 | Q2: =ROUND('Sheet1 (4)'!W8/100,2) -> 0.13 | R2: =ROUND('Sheet1 (4)'!X8/100,2) -> 0.15 | S2: =ROUND('Sheet1 (4)'!Y8/100,2) -> 0.15 | T2: =ROUND('Sheet1 (4)'!Z8/100,2) -> 0.15 | U2: =ROUND('Sheet1 (4)'!AA8/100,2) -> 0.13 | V2: ='Sheet1 (4)'!AB8&".T" -> 3457.T | W2: =ROUND('Sheet1 (4)'!AC8,2) -> 8.89 | X2: =ROUND('Sheet1 (4)'!AD8,2) -> 1.14 | Y2: =_xlfn.XLOOKUP('Sheet1 (4)'!AB8,'Sheet1 (3)'!B:B,'Sheet1 (3)'!D:D,"",0) -> プライム
A3: 2 | B3: =_xlfn.XLOOKUP('Sheet1 (4)'!AB9,'Sheet1 (3)'!B:B,'Sheet1 (3)'!C:C,"",0) -> スリー・ディー・マトリックス | C3: =_xlfn.XLOOKUP('Sheet1 (4)'!AB9,'Sheet1 (3)'!B:B,'Sheet1 (3)'!F:F,"",0) -> 精密機器 | D3: =ROUND('Sheet1 (4)'!E9/100000000,2) -> 1.14 | E3: =ROUND('Sheet1 (4)'!F9/100,2) -> -26.49 | F3: =ROUND('Sheet1 (4)'!G9/100,2) -> -27.36 | G3: =ROUND('Sheet1 (4)'!H9/100,2) -> -31.58 | H3: =ROUND('Sheet1 (4)'!I9/100,2) -> -21.17 | I3: =ROUND('Sheet1 (4)'!J9/100,2) -> -11.56 | J3: =ROUND('Sheet1 (4)'!K9/100,2) -> #VALUE! | K3: =ROUND('Sheet1 (4)'!L9/100,2) -> #VALUE! | L3: =ROUND(('Sheet1 (4)'!M9+'Sheet1 (4)'!R9)/100,2) -> -34.09 | M3: =ROUND(('Sheet1 (4)'!N9+'Sheet1 (4)'!S9)/100,2) -> -29.82 | N3: =ROUND(('Sheet1 (4)'!O9+'Sheet1 (4)'!T9)/100,2) -> -46.66 | O3: =ROUND(('Sheet1 (4)'!P9+'Sheet1 (4)'!U9)/100,2) -> -19.28 | P3: =ROUND(('Sheet1 (4)'!Q9+'Sheet1 (4)'!V9)/100,2) -> -17.47 | Q3: =ROUND('Sheet1 (4)'!W9/100,2) -> -1.89 | R3: =ROUND('Sheet1 (4)'!X9/100,2) -> -1.21 | S3: =ROUND('Sheet1 (4)'!Y9/100,2) -> -2.47 | T3: =ROUND('Sheet1 (4)'!Z9/100,2) -> -0.58 | U3: =ROUND('Sheet1 (4)'!AA9/100,2) -> -1.95 | V3: ='Sheet1 (4)'!AB9&".T" -> 7777.T | W3: =ROUND('Sheet1 (4)'!AC9,2) -> #VALUE! | X3: =ROUND('Sheet1 (4)'!AD9,2) -> 13.56 | Y3: =_xlfn.XLOOKUP('Sheet1 (4)'!AB9,'Sheet1 (3)'!B:B,'Sheet1 (3)'!D:D,"",0) -> グロース
A4: 3 | B4: =_xlfn.XLOOKUP('Sheet1 (4)'!AB10,'Sheet1 (3)'!B:B,'Sheet1 (3)'!C:C,"",0) -> フォーシーズＨＤ | C4: =_xlfn.XLOOKUP('Sheet1 (4)'!AB10,'Sheet1 (3)'!B:B,'Sheet1 (3)'!F:F,"",0) -> 小売業 | D4: =ROUND('Sheet1 (4)'!E10/100000000,2) -> 0.11 | E4: =ROUND('Sheet1 (4)'!F10/100,2) -> -1.48 | F4: =ROUND('Sheet1 (4)'!G10/100,2) -> -1.19 | G4: =ROUND('Sheet1 (4)'!H10/100,2) -> -2.15 | H4: =ROUND('Sheet1 (4)'!I10/100,2) -> -1.26 | I4: =ROUND('Sheet1 (4)'!J10/100,2) -> -1.26 | J4: =ROUND('Sheet1 (4)'!K10/100,2) -> #VALUE! | K4: =ROUND('Sheet1 (4)'!L10/100,2) -> #VALUE! | L4: =ROUND(('Sheet1 (4)'!M10+'Sheet1 (4)'!R10)/100,2) -> -1.14 | M4: =ROUND(('Sheet1 (4)'!N10+'Sheet1 (4)'!S10)/100,2) -> -0.45 | N4: =ROUND(('Sheet1 (4)'!O10+'Sheet1 (4)'!T10)/100,2) -> -4.26 | O4: =ROUND(('Sheet1 (4)'!P10+'Sheet1 (4)'!U10)/100,2) -> -4.11 | P4: =ROUND(('Sheet1 (4)'!Q10+'Sheet1 (4)'!V10)/100,2) -> -4.11 | Q4: =ROUND('Sheet1 (4)'!W10/100,2) -> -0.28 | R4: =ROUND('Sheet1 (4)'!X10/100,2) -> -0.3 | S4: =ROUND('Sheet1 (4)'!Y10/100,2) -> -0.56 | T4: =ROUND('Sheet1 (4)'!Z10/100,2) -> -0.32 | U4: =ROUND('Sheet1 (4)'!AA10/100,2) -> -0.32 | V4: ='Sheet1 (4)'!AB10&".T" -> 3726.T | W4: =ROUND('Sheet1 (4)'!AC10,2) -> #VALUE! | X4: =ROUND('Sheet1 (4)'!AD10,2) -> 3.53 | Y4: =_xlfn.XLOOKUP('Sheet1 (4)'!AB10,'Sheet1 (3)'!B:B,'Sheet1 (3)'!D:D,"",0) -> スタンダード
A5: 4 | B5: =_xlfn.XLOOKUP('Sheet1 (4)'!AB11,'Sheet1 (3)'!B:B,'Sheet1 (3)'!C:C,"",0) -> エーアンドエーマテリアル | C5: =_xlfn.XLOOKUP('Sheet1 (4)'!AB11,'Sheet1 (3)'!B:B,'Sheet1 (3)'!F:F,"",0) -> ガラス・土石製品 | D5: =ROUND('Sheet1 (4)'!E11/100000000,2) -> 0.08 | E5: =ROUND('Sheet1 (4)'!F11/100,2) -> 14.72 | F5: =ROUND('Sheet1 (4)'!G11/100,2) -> 14.41 | G5: =ROUND('Sheet1 (4)'!H11/100,2) -> 14.91 | H5: =ROUND('Sheet1 (4)'!I11/100,2) -> 23.2 | I5: =ROUND('Sheet1 (4)'!J11/100,2) -> 19.17 | J5: =ROUND('Sheet1 (4)'!K11/100,2) -> #VALUE! | K5: =ROUND('Sheet1 (4)'!L11/100,2) -> #VALUE! | L5: =ROUND(('Sheet1 (4)'!M11+'Sheet1 (4)'!R11)/100,2) -> -1.39 | M5: =ROUND(('Sheet1 (4)'!N11+'Sheet1 (4)'!S11)/100,2) -> 0.87 | N5: =ROUND(('Sheet1 (4)'!O11+'Sheet1 (4)'!T11)/100,2) -> -10.11 | O5: =ROUND(('Sheet1 (4)'!P11+'Sheet1 (4)'!U11)/100,2) -> 35.8 | P5: =ROUND(('Sheet1 (4)'!Q11+'Sheet1 (4)'!V11)/100,2) -> -13.94 | Q5: =ROUND('Sheet1 (4)'!W11/100,2) -> 0.05 | R5: =ROUND('Sheet1 (4)'!X11/100,2) -> 0.06 | S5: =ROUND('Sheet1 (4)'!Y11/100,2) -> 0.06 | T5: =ROUND('Sheet1 (4)'!Z11/100,2) -> 0.15 | U5: =ROUND('Sheet1 (4)'!AA11/100,2) -> -0.01 | V5: ='Sheet1 (4)'!AB11&".T" -> 5391.T | W5: =ROUND('Sheet1 (4)'!AC11,2) -> 90.58 | X5: =ROUND('Sheet1 (4)'!AD11,2) -> 0.49 | Y5: =_xlfn.XLOOKUP('Sheet1 (4)'!AB11,'Sheet1 (3)'!B:B,'Sheet1 (3)'!D:D,"",0) -> スタンダード
A6: 5 | B6: =_xlfn.XLOOKUP('Sheet1 (4)'!AB12,'Sheet1 (3)'!B:B,'Sheet1 (3)'!C:C,"",0) -> Ａ＆Ｄホロンホールディングス | C6: =_xlfn.XLOOKUP('Sheet1 (4)'!AB12,'Sheet1 (3)'!B:B,'Sheet1 (3)'!F:F,"",0) -> 精密機器 | D6: =ROUND('Sheet1 (4)'!E12/100000000,2) -> 0.27 | E6: =ROUND('Sheet1 (4)'!F12/100,2) -> 44.05 | F6: =ROUND('Sheet1 (4)'!G12/100,2) -> 54.97 | G6: =ROUND('Sheet1 (4)'!H12/100,2) -> 74.76 | H6: =ROUND('Sheet1 (4)'!I12/100,2) -> 79.56 | I6: =ROUND('Sheet1 (4)'!J12/100,2) -> 88.13 | J6: =ROUND('Sheet1 (4)'!K12/100,2) -> 94.23 | K6: =ROUND('Sheet1 (4)'!L12/100,2) -> 98.9 | L6: =ROUND(('Sheet1 (4)'!M12+'Sheet1 (4)'!R12)/100,2) -> 29.72 | M6: =ROUND(('Sheet1 (4)'!N12+'Sheet1 (4)'!S12)/100,2) -> -6.13 | N6: =ROUND(('Sheet1 (4)'!O12+'Sheet1 (4)'!T12)/100,2) -> 27.32 | O6: =ROUND(('Sheet1 (4)'!P12+'Sheet1 (4)'!U12)/100,2) -> 51.94 | P6: =ROUND(('Sheet1 (4)'!Q12+'Sheet1 (4)'!V12)/100,2) -> 45.73 | Q6: =ROUND('Sheet1 (4)'!W12/100,2) -> 0.17 | R6: =ROUND('Sheet1 (4)'!X12/100,2) -> 0.16 | S6: =ROUND('Sheet1 (4)'!Y12/100,2) -> 0.19 | T6: =ROUND('Sheet1 (4)'!Z12/100,2) -> 0.15 | U6: =ROUND('Sheet1 (4)'!AA12/100,2) -> 0.16 | V6: ='Sheet1 (4)'!AB12&".T" -> 7745.T | W6: =ROUND('Sheet1 (4)'!AC12,2) -> 8.36 | X6: =ROUND('Sheet1 (4)'!AD12,2) -> 1.21 | Y6: =_xlfn.XLOOKUP('Sheet1 (4)'!AB12,'Sheet1 (3)'!B:B,'Sheet1 (3)'!D:D,"",0) -> プライム
A7: 6 | B7: =_xlfn.XLOOKUP('Sheet1 (4)'!AB13,'Sheet1 (3)'!B:B,'Sheet1 (3)'!C:C,"",0) -> ＡＤワークスグループ | C7: =_xlfn.XLOOKUP('Sheet1 (4)'!AB13,'Sheet1 (3)'!B:B,'Sheet1 (3)'!F:F,"",0) -> 不動産業 | D7: =ROUND('Sheet1 (4)'!E13/100000000,2) -> 0.49 | E7: =ROUND('Sheet1 (4)'!F13/100,2) -> 9.27 | F7: =ROUND('Sheet1 (4)'!G13/100,2) -> 13.7 | G7: =ROUND('Sheet1 (4)'!H13/100,2) -> 24.35 | H7: =ROUND('Sheet1 (4)'!I13/100,2) -> 32.09 | I7: =ROUND('Sheet1 (4)'!J13/100,2) -> 32.09 | J7: =ROUND('Sheet1 (4)'!K13/100,2) -> #VALUE! | K7: =ROUND('Sheet1 (4)'!L13/100,2) -> #VALUE! | L7: =ROUND(('Sheet1 (4)'!M13+'Sheet1 (4)'!R13)/100,2) -> -45.86 | M7: =ROUND(('Sheet1 (4)'!N13+'Sheet1 (4)'!S13)/100,2) -> -113.12 | N7: =ROUND(('Sheet1 (4)'!O13+'Sheet1 (4)'!T13)/100,2) -> -8.29 | O7: =ROUND(('Sheet1 (4)'!P13+'Sheet1 (4)'!U13)/100,2) -> 13.96 | P7: =ROUND(('Sheet1 (4)'!Q13+'Sheet1 (4)'!V13)/100,2) -> 13.96 | Q7: =ROUND('Sheet1 (4)'!W13/100,2) -> 0.02 | R7: =ROUND('Sheet1 (4)'!X13/100,2) -> 0.04 | S7: =ROUND('Sheet1 (4)'!Y13/100,2) -> 0.09 | T7: =ROUND('Sheet1 (4)'!Z13/100,2) -> 0.09 | U7: =ROUND('Sheet1 (4)'!AA13/100,2) -> 0.09 | V7: ='Sheet1 (4)'!AB13&".T" -> 2982.T | W7: =ROUND('Sheet1 (4)'!AC13,2) -> 9.92 | X7: =ROUND('Sheet1 (4)'!AD13,2) -> 1.15 | Y7: =_xlfn.XLOOKUP('Sheet1 (4)'!AB13,'Sheet1 (3)'!B:B,'Sheet1 (3)'!D:D,"",0) -> プライム
A8: 7 | B8: =_xlfn.XLOOKUP('Sheet1 (4)'!AB14,'Sheet1 (3)'!B:B,'Sheet1 (3)'!C:C,"",0) -> ＡＢ＆Ｃｏｍｐａｎｙ | C8: =_xlfn.XLOOKUP('Sheet1 (4)'!AB14,'Sheet1 (3)'!B:B,'Sheet1 (3)'!F:F,"",0) -> サービス業 | D8: =ROUND('Sheet1 (4)'!E14/100000000,2) -> 0.14 | E8: =ROUND('Sheet1 (4)'!F14/100,2) -> 15.26 | F8: =ROUND('Sheet1 (4)'!G14/100,2) -> 13.68 | G8: =ROUND('Sheet1 (4)'!H14/100,2) -> 18.52 | H8: =ROUND('Sheet1 (4)'!I14/100,2) -> 16.79 | I8: =ROUND('Sheet1 (4)'!J14/100,2) -> 16.79 | J8: =ROUND('Sheet1 (4)'!K14/100,2) -> 17.5 | K8: =ROUND('Sheet1 (4)'!L14/100,2) -> 18.5 | L8: =ROUND(('Sheet1 (4)'!M14+'Sheet1 (4)'!R14)/100,2) -> 17.72 | M8: =ROUND(('Sheet1 (4)'!N14+'Sheet1 (4)'!S14)/100,2) -> 15.85 | N8: =ROUND(('Sheet1 (4)'!O14+'Sheet1 (4)'!T14)/100,2) -> 20.77 | O8: =ROUND(('Sheet1 (4)'!P14+'Sheet1 (4)'!U14)/100,2) -> 27.11 | P8: =ROUND(('Sheet1 (4)'!Q14+'Sheet1 (4)'!V14)/100,2) -> 27.11 | Q8: =ROUND('Sheet1 (4)'!W14/100,2) -> 0.15 | R8: =ROUND('Sheet1 (4)'!X14/100,2) -> 0.11 | S8: =ROUND('Sheet1 (4)'!Y14/100,2) -> 0.13 | T8: =ROUND('Sheet1 (4)'!Z14/100,2) -> 0.13 | U8: =ROUND('Sheet1 (4)'!AA14/100,2) -> 0.13 | V8: ='Sheet1 (4)'!AB14&".T" -> 9251.T | W8: =ROUND('Sheet1 (4)'!AC14,2) -> 15.04 | X8: =ROUND('Sheet1 (4)'!AD14,2) -> 1.71 | Y8: =_xlfn.XLOOKUP('Sheet1 (4)'!AB14,'Sheet1 (3)'!B:B,'Sheet1 (3)'!D:D,"",0) -> グロース
A9: 8 | B9: =_xlfn.XLOOKUP('Sheet1 (4)'!AB15,'Sheet1 (3)'!B:B,'Sheet1 (3)'!C:C,"",0) -> Ａｂａｌａｎｃｅ | C9: =_xlfn.XLOOKUP('Sheet1 (4)'!AB15,'Sheet1 (3)'!B:B,'Sheet1 (3)'!F:F,"",0) -> 電気機器 | D9: =ROUND('Sheet1 (4)'!E15/100000000,2) -> 0.19 | E9: =ROUND('Sheet1 (4)'!F15/100,2) -> 13.62 | F9: =ROUND('Sheet1 (4)'!G15/100,2) -> 15.81 | G9: =ROUND('Sheet1 (4)'!H15/100,2) -> 128.05 | H9: =ROUND('Sheet1 (4)'!I15/100,2) -> 232.68 | I9: =ROUND('Sheet1 (4)'!J15/100,2) -> 48.17 | J9: =ROUND('Sheet1 (4)'!K15/100,2) -> #VALUE! | K9: =ROUND('Sheet1 (4)'!L15/100,2) -> #VALUE! | L9: =ROUND(('Sheet1 (4)'!M15+'Sheet1 (4)'!R15)/100,2) -> -19.99 | M9: =ROUND(('Sheet1 (4)'!N15+'Sheet1 (4)'!S15)/100,2) -> -196.7 | N9: =ROUND(('Sheet1 (4)'!O15+'Sheet1 (4)'!T15)/100,2) -> -21.44 | O9: =ROUND(('Sheet1 (4)'!P15+'Sheet1 (4)'!U15)/100,2) -> 235.66 | P9: =ROUND(('Sheet1 (4)'!Q15+'Sheet1 (4)'!V15)/100,2) -> -173.08 | Q9: =ROUND('Sheet1 (4)'!W15/100,2) -> 0.27 | R9: =ROUND('Sheet1 (4)'!X15/100,2) -> 0.24 | S9: =ROUND('Sheet1 (4)'!Y15/100,2) -> 0.78 | T9: =ROUND('Sheet1 (4)'!Z15/100,2) -> 0.62 | U9: =ROUND('Sheet1 (4)'!AA15/100,2) -> #VALUE! | V9: ='Sheet1 (4)'!AB15&".T" -> 3856.T | W9: =ROUND('Sheet1 (4)'!AC15,2) -> 14.1 | X9: =ROUND('Sheet1 (4)'!AD15,2) -> 0.73 | Y9: =_xlfn.XLOOKUP('Sheet1 (4)'!AB15,'Sheet1 (3)'!B:B,'Sheet1 (3)'!D:D,"",0) -> スタンダード
A10: 9 | B10: =_xlfn.XLOOKUP('Sheet1 (4)'!AB16,'Sheet1 (3)'!B:B,'Sheet1 (3)'!C:C,"",0) -> ａｂｃ | C10: =_xlfn.XLOOKUP('Sheet1 (4)'!AB16,'Sheet1 (3)'!B:B,'Sheet1 (3)'!F:F,"",0) -> その他金融業 | D10: =ROUND('Sheet1 (4)'!E16/100000000,2) -> 0.29 | E10: =ROUND('Sheet1 (4)'!F16/100,2) -> -14.65 | F10: =ROUND('Sheet1 (4)'!G16/100,2) -> -6.99 | G10: =ROUND('Sheet1 (4)'!H16/100,2) -> -19.14 | H10: =ROUND('Sheet1 (4)'!I16/100,2) -> -21.16 | I10: =ROUND('Sheet1 (4)'!J16/100,2) -> -26.15 | J10: =ROUND('Sheet1 (4)'!K16/100,2) -> #VALUE! | K10: =ROUND('Sheet1 (4)'!L16/100,2) -> #VALUE! | L10: =ROUND(('Sheet1 (4)'!M16+'Sheet1 (4)'!R16)/100,2) -> -1.64 | M10: =ROUND(('Sheet1 (4)'!N16+'Sheet1 (4)'!S16)/100,2) -> -12 | N10: =ROUND(('Sheet1 (4)'!O16+'Sheet1 (4)'!T16)/100,2) -> -42.09 | O10: =ROUND(('Sheet1 (4)'!P16+'Sheet1 (4)'!U16)/100,2) -> -20.97 | P10: =ROUND(('Sheet1 (4)'!Q16+'Sheet1 (4)'!V16)/100,2) -> -58.45 | Q10: =ROUND('Sheet1 (4)'!W16/100,2) -> -2.2 | R10: =ROUND('Sheet1 (4)'!X16/100,2) -> -4.5 | S10: =ROUND('Sheet1 (4)'!Y16/100,2) -> -2.56 | T10: =ROUND('Sheet1 (4)'!Z16/100,2) -> -3.29 | U10: =ROUND('Sheet1 (4)'!AA16/100,2) -> -2.93 | V10: ='Sheet1 (4)'!AB16&".T" -> 8783.T | W10: =ROUND('Sheet1 (4)'!AC16,2) -> #VALUE! | X10: =ROUND('Sheet1 (4)'!AD16,2) -> 2.2 | Y10: =_xlfn.XLOOKUP('Sheet1 (4)'!AB16,'Sheet1 (3)'!B:B,'Sheet1 (3)'!D:D,"",0) -> スタンダード
A11: 10 | B11: =_xlfn.XLOOKUP('Sheet1 (4)'!AB17,'Sheet1 (3)'!B:B,'Sheet1 (3)'!C:C,"",0) -> エービーシー・マート | C11: =_xlfn.XLOOKUP('Sheet1 (4)'!AB17,'Sheet1 (3)'!B:B,'Sheet1 (3)'!F:F,"",0) -> 小売業 | D11: =ROUND('Sheet1 (4)'!E17/100000000,2) -> 2.48 | E11: =ROUND('Sheet1 (4)'!F17/100,2) -> 195.15 | F11: =ROUND('Sheet1 (4)'!G17/100,2) -> 274.48 | G11: =ROUND('Sheet1 (4)'!H17/100,2) -> 423.02 | H11: =ROUND('Sheet1 (4)'!I17/100,2) -> 556.72 | I11: =ROUND('Sheet1 (4)'!J17/100,2) -> 625.51 | J11: =ROUND('Sheet1 (4)'!K17/100,2) -> 648.22 | K11: =ROUND('Sheet1 (4)'!L17/100,2) -> 674.87 | L11: =ROUND(('Sheet1 (4)'!M17+'Sheet1 (4)'!R17)/100,2) -> 121.71 | M11: =ROUND(('Sheet1 (4)'!N17+'Sheet1 (4)'!S17)/100,2) -> 176.99 | N11: =ROUND(('Sheet1 (4)'!O17+'Sheet1 (4)'!T17)/100,2) -> 18.79 | O11: =ROUND(('Sheet1 (4)'!P17+'Sheet1 (4)'!U17)/100,2) -> 398.25 | P11: =ROUND(('Sheet1 (4)'!Q17+'Sheet1 (4)'!V17)/100,2) -> 410.22 | Q11: =ROUND('Sheet1 (4)'!W17/100,2) -> 0.07 | R11: =ROUND('Sheet1 (4)'!X17/100,2) -> 0.06 | S11: =ROUND('Sheet1 (4)'!Y17/100,2) -> 0.1 | T11: =ROUND('Sheet1 (4)'!Z17/100,2) -> 0.12 | U11: =ROUND('Sheet1 (4)'!AA17/100,2) -> 0.13 | V11: ='Sheet1 (4)'!AB17&".T" -> 2670.T | W11: =ROUND('Sheet1 (4)'!AC17,2) -> 14.52 | X11: =ROUND('Sheet1 (4)'!AD17,2) -> 1.74 | Y11: =_xlfn.XLOOKUP('Sheet1 (4)'!AB17,'Sheet1 (3)'!B:B,'Sheet1 (3)'!D:D,"",0) -> プライム
A12: 11 | B12: =_xlfn.XLOOKUP('Sheet1 (4)'!AB18,'Sheet1 (3)'!B:B,'Sheet1 (3)'!C:C,"",0) -> ＡＢＥＪＡ | C12: =_xlfn.XLOOKUP('Sheet1 (4)'!AB18,'Sheet1 (3)'!B:B,'Sheet1 (3)'!F:F,"",0) -> 情報・通信業 | D12: =ROUND('Sheet1 (4)'!E18/100000000,2) -> 0.09 | E12: =ROUND('Sheet1 (4)'!F18/100,2) -> -2.65 | F12: =ROUND('Sheet1 (4)'!G18/100,2) -> -1.63 | G12: =ROUND('Sheet1 (4)'!H18/100,2) -> 4.03 | H12: =ROUND('Sheet1 (4)'!I18/100,2) -> 2.91 | I12: =ROUND('Sheet1 (4)'!J18/100,2) -> 4.46 | J12: =ROUND('Sheet1 (4)'!K18/100,2) -> 4.8 | K12: =ROUND('Sheet1 (4)'!L18/100,2) -> 5.99 | L12: =ROUND(('Sheet1 (4)'!M18+'Sheet1 (4)'!R18)/100,2) -> #VALUE! | M12: =ROUND(('Sheet1 (4)'!N18+'Sheet1 (4)'!S18)/100,2) -> #VALUE! | N12: =ROUND(('Sheet1 (4)'!O18+'Sheet1 (4)'!T18)/100,2) -> 4.55 | O12: =ROUND(('Sheet1 (4)'!P18+'Sheet1 (4)'!U18)/100,2) -> -7.88 | P12: =ROUND(('Sheet1 (4)'!Q18+'Sheet1 (4)'!V18)/100,2) -> 15.93 | Q12: =ROUND('Sheet1 (4)'!W18/100,2) -> #VALUE! | R12: =ROUND('Sheet1 (4)'!X18/100,2) -> -0.1 | S12: =ROUND('Sheet1 (4)'!Y18/100,2) -> 0.16 | T12: =ROUND('Sheet1 (4)'!Z18/100,2) -> 0.06 | U12: =ROUND('Sheet1 (4)'!AA18/100,2) -> 0.11 | V12: ='Sheet1 (4)'!AB18&".T" -> 5574.T | W12: =ROUND('Sheet1 (4)'!AC18,2) -> 63.36 | X12: =ROUND('Sheet1 (4)'!AD18,2) -> 5.97 | Y12: =_xlfn.XLOOKUP('Sheet1 (4)'!AB18,'Sheet1 (3)'!B:B,'Sheet1 (3)'!D:D,"",0) -> グロース
A13: 12 | B13: =_xlfn.XLOOKUP('Sheet1 (4)'!AB19,'Sheet1 (3)'!B:B,'Sheet1 (3)'!C:C,"",0) -> ＡＢホテル | C13: =_xlfn.XLOOKUP('Sheet1 (4)'!AB19,'Sheet1 (3)'!B:B,'Sheet1 (3)'!F:F,"",0) -> サービス業 | D13: =ROUND('Sheet1 (4)'!E19/100000000,2) -> 0.14 | E13: =ROUND('Sheet1 (4)'!F19/100,2) -> 0.45 | F13: =ROUND('Sheet1 (4)'!G19/100,2) -> 9.59 | G13: =ROUND('Sheet1 (4)'!H19/100,2) -> 29.77 | H13: =ROUND('Sheet1 (4)'!I19/100,2) -> 36.12 | I13: =ROUND('Sheet1 (4)'!J19/100,2) -> 39.63 | J13: =ROUND('Sheet1 (4)'!K19/100,2) -> #VALUE! | K13: =ROUND('Sheet1 (4)'!L19/100,2) -> #VALUE! | L13: =ROUND(('Sheet1 (4)'!M19+'Sheet1 (4)'!R19)/100,2) -> -20.75 | M13: =ROUND(('Sheet1 (4)'!N19+'Sheet1 (4)'!S19)/100,2) -> 15.4 | N13: =ROUND(('Sheet1 (4)'!O19+'Sheet1 (4)'!T19)/100,2) -> 28.02 | O13: =ROUND(('Sheet1 (4)'!P19+'Sheet1 (4)'!U19)/100,2) -> 16.81 | P13: =ROUND(('Sheet1 (4)'!Q19+'Sheet1 (4)'!V19)/100,2) -> -5.01 | Q13: =ROUND('Sheet1 (4)'!W19/100,2) -> 0 | R13: =ROUND('Sheet1 (4)'!X19/100,2) -> 0.09 | S13: =ROUND('Sheet1 (4)'!Y19/100,2) -> 0.24 | T13: =ROUND('Sheet1 (4)'!Z19/100,2) -> 0.25 | U13: =ROUND('Sheet1 (4)'!AA19/100,2) -> 0.22 | V13: ='Sheet1 (4)'!AB19&".T" -> 6565.T | W13: =ROUND('Sheet1 (4)'!AC19,2) -> 8.54 | X13: =ROUND('Sheet1 (4)'!AD19,2) -> 1.74 | Y13: =_xlfn.XLOOKUP('Sheet1 (4)'!AB19,'Sheet1 (3)'!B:B,'Sheet1 (3)'!D:D,"",0) -> スタンダード
... A4226: 4225 | B4226: =_xlfn.XLOOKUP('Sheet1 (4)'!AB4232,'Sheet1 (3)'!B:B,'Sheet1 (3)'!C:C,"",0) -> 0 | C4226: =_xlfn.XLOOKUP('Sheet1 (4)'!AB4232,'Sheet1 (3)'!B:B,'Sheet1 (3)'!F:F,"",0) -> 0 | D4226: =ROUND('Sheet1 (4)'!E4232/100000000,2) -> 0 | E4226: =ROUND('Sheet1 (4)'!F4232/100,2) -> 0 | F4226: =ROUND('Sheet1 (4)'!G4232/100,2) -> 0 | G4226: =ROUND('Sheet1 (4)'!H4232/100,2) -> 0 | H4226: =ROUND('Sheet1 (4)'!I4232/100,2) -> 0 | I4226: =ROUND('Sheet1 (4)'!J4232/100,2) -> 0 | J4226: =ROUND('Sheet1 (4)'!K4232/100,2) -> 0 | K4226: =ROUND('Sheet1 (4)'!L4232/100,2) -> 0 | L4226: =ROUND(('Sheet1 (4)'!M4232+'Sheet1 (4)'!R4232)/100,2) -> 0 | M4226: =ROUND(('Sheet1 (4)'!N4232+'Sheet1 (4)'!S4232)/100,2) -> 0 | N4226: =ROUND(('Sheet1 (4)'!O4232+'Sheet1 (4)'!T4232)/100,2) -> 0 | O4226: =ROUND(('Sheet1 (4)'!P4232+'Sheet1 (4)'!U4232)/100,2) -> 0 | P4226: =ROUND(('Sheet1 (4)'!Q4232+'Sheet1 (4)'!V4232)/100,2) -> 0 | Q4226: =ROUND('Sheet1 (4)'!W4232/100,2) -> 0 | R4226: =ROUND('Sheet1 (4)'!X4232/100,2) -> 0 | S4226: =ROUND('Sheet1 (4)'!Y4232/100,2) -> 0 | T4226: =ROUND('Sheet1 (4)'!Z4232/100,2) -> 0 | U4226: =ROUND('Sheet1 (4)'!AA4232/100,2) -> 0 | V4226: ='Sheet1 (4)'!AB4232&".T" -> .T | W4226: =ROUND('Sheet1 (4)'!AC4232,2) -> 0 | X4226: =ROUND('Sheet1 (4)'!AD4232,2) -> 0 | Y4226: =_xlfn.XLOOKUP('Sheet1 (4)'!AB4232,'Sheet1 (3)'!B:B,'Sheet1 (3)'!D:D,"",0) -> 0

Sheet Sheet1 (3)
A1: 日付 | B1: コード | C1: 銘柄名 | D1: 市場・商品区分 | E1: 33業種コード | F1: 33業種区分 | G1: 17業種コード | H1: 17業種区分 | I1: 規模コード | J1: 規模区分
A2: 20251031 | B2: 1301 | C2: 極洋 | D2: プライム | E2: 50 | F2: 水産・農林業 | G2: 1 | H2: 食品 | I2: 6 | J2: TOPIX Small 1
A3: 20251031 | B3: 1305 | C3: ｉＦｒｅｅＥＴＦ ＴＯＰＩＸ（年１回決算型） | D3: ETF・ETN | E3: - | F3: - | G3: - | H3: - | I3: - | J3: -
A4: 20251031 | B4: 1306 | C4: ＮＥＸＴ ＦＵＮＤＳ ＴＯＰＩＸ連動型上場投信 | D4: ETF・ETN | E4: - | F4: - | G4: - | H4: - | I4: - | J4: -
A5: 20251031 | B5: 1308 | C5: 上場インデックスファンドＴＯＰＩＸ | D5: ETF・ETN | E5: - | F5: - | G5: - | H5: - | I5: - | J5: -
A6: 20251031 | B6: 1309 | C6: ＮＥＸＴ ＦＵＮＤＳ ＣｈｉｎａＡＭＣ・中国株式・上証５０連動型上場投信 | D6: ETF・ETN | E6: - | F6: - | G6: - | H6: - | I6: - | J6: -
A7: 20251031 | B7: 130A | C7: Ｖｅｒｉｔａｓ Ｉｎ Ｓｉｌｉｃｏ | D7: グロース | E7: 3250 | F7: 医薬品 | G7: 5 | H7: 医薬品 | I7: - | J7: -
A8: 20251031 | B8: 1311 | C8: ＮＥＸＴ ＦＵＮＤＳ ＴＯＰＩＸ Ｃｏｒｅ ３０連動型上場投信 | D8: ETF・ETN | E8: - | F8: - | G8: - | H8: - | I8: - | J8: -
A9: 20251031 | B9: 1319 | C9: ＮＥＸＴ ＦＵＮＤＳ 日経３００株価指数連動型上場投信 | D9: ETF・ETN | E9: - | F9: - | G9: - | H9: - | I9: - | J9: -
A10: 20251031 | B10: 131A | C10: ＣＣＮグループ | D10: PRO Market | E10: 5250 | F10: 情報・通信業 | G10: 10 | H10: 情報通信・サービスその他 | I10: - | J10: -
A11: 20251031 | B11: 1320 | C11: ｉＦｒｅｅＥＴＦ 日経２２５（年１回決算型） | D11: ETF・ETN | E11: - | F11: - | G11: - | H11: - | I11: - | J11: -
A12: 20251031 | B12: 1321 | C12: ＮＥＸＴ ＦＵＮＤＳ 日経２２５連動型上場投信 | D12: ETF・ETN | E12: - | F12: - | G12: - | H12: - | I12: - | J12: -
A13: 20251031 | B13: 1322 | C13: 上場インデックスファンド中国Ａ株（パンダ）Ｅ Ｆｕｎｄ ＣＳＩ３００ | D13: ETF・ETN | E13: - | F13: - | G13: - | H13: - | I13: - | J13: -
A14: 20251031 | B14: 1325 | C14: ＮＥＸＴ ＦＵＮＤＳ ブラジル株式指数・ボベスパ連動型上場投信 | D14: ETF・ETN | E14: - | F14: - | G14: - | H14: - | I14: - | J14: -
A15: 20251031 | B15: 1326 | C15: ＳＰＤＲゴールド・シェア | D15: ETF・ETN | E15: - | F15: - | G15: - | H15: - | I15: - | J15: -
A16: 20251031 | B16: 1328 | C16: ＮＥＸＴ ＦＵＮＤＳ 金価格連動型上場投信 | D16: ETF・ETN | E16: - | F16: - | G16: - | H16: - | I16: - | J16: -
A17: 20251031 | B17: 1329 | C17: ｉシェアーズ・コア 日経２２５ ＥＴＦ | D17: ETF・ETN | E17: - | F17: - | G17: - | H17: - | I17: - | J17: -
A18: 20251031 | B18: 132A | C18: アイエヌホールディングス | D18: PRO Market | E18: 5050 | F18: 陸運業 | G18: 12 | H18: 運輸・物流 | I18: - | J18: -
A19: 20251031 | B19: 1330 | C19: 上場インデックスファンド２２５ | D19: ETF・ETN | E19: - | F19: - | G19: - | H19: - | I19: - | J19: -
A20: 20251031 | B20: 1332 | C20: ニッスイ | D20: プライム | E20: 50 | F20: 水産・農林業 | G20: 1 | H20: 食品 | I20: 4 | J20: TOPIX Mid400
A21: 20251031 | B21: 1333 | C21: マルハニチロ | D21: プライム | E21: 50 | F21: 水産・農林業 | G21: 1 | H21: 食品 | I21: 4 | J21: TOPIX Mid400
A22: 20251031 | B22: 133A | C22: グローバルＸ 超短期米国債 ＥＴＦ | D22: ETF・ETN | E22: - | F22: - | G22: - | H22: - | I22: - | J22: -
A23: 20251031 | B23: 1343 | C23: ＮＥＸＴ ＦＵＮＤＳ 東証ＲＥＩＴ 指数連動型上場投信 | D23: ETF・ETN | E23: - | F23: - | G23: - | H23: - | I23: - | J23: -
A24: 20251031 | B24: 1345 | C24: 上場インデックスファンドＪリート（東証ＲＥＩＴ指数）隔月分配型 | D24: ETF・ETN | E24: - | F24: - | G24: - | H24: - | I24: - | J24: -
A25: 20251031 | B25: 1346 | C25: ＭＡＸＩＳ 日経２２５上場投信 | D25: ETF・ETN | E25: - | F25: - | G25: - | H25: - | I25: - | J25: -
A26: 20251031 | B26: 1348 | C26: ＭＡＸＩＳ トピックス上場投信 | D26: ETF・ETN | E26: - | F26: - | G26: - | H26: - | I26: - | J26: -
A27: 20251031 | B27: 1349 | C27: ＡＢＦ汎アジア債券インデックス・ファンド | D27: ETF・ETN | E27: - | F27: - | G27: - | H27: - | I27: - | J27: -
A28: 20251031 | B28: 134A | C28: アプライズ | D28: PRO Market | E28: 9050 | F28: サービス業 | G28: 10 | H28: 情報通信・サービスその他 | I28: - | J28: -
A29: 20251031 | B29: 1356 | C29: ＴＯＰＩＸベア２倍上場投信 | D29: ETF・ETN | E29: - | F29: - | G29: - | H29: - | I29: - | J29: -
A30: 20251031 | B30: 1357 | C30: ＮＥＸＴ ＦＵＮＤＳ 日経平均ダブルインバース・インデックス連動型上場投信 | D30: ETF・ETN | E30: - | F30: - | G30: - | H30: - | I30: - | J30: -
A31: 20251031 | B31: 1358 | C31: 上場インデックスファンド日経レバレッジ指数 | D31: ETF・ETN | E31: - | F31: - | G31: - | H31: - | I31: - | J31: -
A32: 20251031 | B32: 135A | C32: ＶＲＡＩＮ Ｓｏｌｕｔｉｏｎ | D32: グロース | E32: 5250 | F32: 情報・通信業 | G32: 10 | H32: 情報通信・サービスその他 | I32: - | J32: -
A33: 20251031 | B33: 1360 | C33: 日経平均ベア２倍上場投信 | D33: ETF・ETN | E33: - | F33: - | G33: - | H33: - | I33: - | J33: -
A34: 20251031 | B34: 1364 | C34: ｉシェアーズ ＪＰＸ日経４００ ＥＴＦ | D34: ETF・ETN | E34: - | F34: - | G34: - | H34: - | I34: - | J34: -
A35: 20251031 | B35: 1365 | C35: ｉＦｒｅｅＥＴＦ 日経平均レバレッジ・インデックス | D35: ETF・ETN | E35: - | F35: - | G35: - | H35: - | I35: - | J35: -
A36: 20251031 | B36: 1366 | C36: ｉＦｒｅｅＥＴＦ 日経平均ダブルインバース・インデックス | D36: ETF・ETN | E36: - | F36: - | G36: - | H36: - | I36: - | J36: -
A37: 20251031 | B37: 1367 | C37: ｉＦｒｅｅＥＴＦ ＴＯＰＩＸレバレッジ（２倍）指数 | D37: ETF・ETN | E37: - | F37: - | G37: - | H37: - | I37: - | J37: -
A38: 20251031 | B38: 1368 | C38: ｉＦｒｅｅＥＴＦ ＴＯＰＩＸダブルインバース（－２倍）指数 | D38: ETF・ETN | E38: - | F38: - | G38: - | H38: - | I38: - | J38: -
A39: 20251031 | B39: 1369 | C39: Ｏｎｅ ＥＴＦ 日経２２５ | D39: ETF・ETN | E39: - | F39: - | G39: - | H39: - | I39: - | J39: -
A40: 20251031 | B40: 136A | C40: 三興商事 | D40: PRO Market | E40: 2050 | F40: 建設業 | G40: 3 | H40: 建設・資材 | I40: - | J40: -
...

Sheet Sheet1 (4)
A3: =SPGTable($B$8:$B$3910,$C$5:$AF$5,$C$6:$AF$6,"Options:Curr=JPY,Mag=Standard,ConvMethod=R,FilingVer=Current/Restated") -> #NAME?
A4: =SPGLabel(266637,267969,"","Options:Curr=JPY,Mag=Standard,ConvMethod=R,FilingVer=Current/Restated") -> #NAME? | B4: =SPGLabel(266637,267961,"","Options:Curr=JPY,Mag=Standard,ConvMethod=R,FilingVer=Current/Restated") -> #NAME? | C4: =SPGLabel(266637,313763,"","Options:Curr=JPY,Mag=Standard,ConvMethod=R,FilingVer=Current/Restated") -> #NAME? | D4: =SPGLabel(266637,268194,"","Options:Curr=JPY,Mag=Standard,ConvMethod=R,FilingVer=Current/Restated") -> #NAME? | E4: =SPGLabel(266637,329044,"11/06/2025","Options:Curr=JPY,Mag=Standard,ConvMethod=R,FilingVer=Current/Restated") -> #NAME? | F4: =SPGLabel(266637,329291,"FY2021","Options:Curr=JPY,Mag=Standard,ConvMethod=R,FilingVer=Current/Restated") -> #NAME? | G4: =SPGLabel(266637,329291,"FY2022","Options:Curr=JPY,Mag=Standard,ConvMethod=R,FilingVer=Current/Restated") -> #NAME? | H4: =SPGLabel(266637,329291,"FY2023","Options:Curr=JPY,Mag=Standard,ConvMethod=R,FilingVer=Current/Restated") -> #NAME? | I4: =SPGLabel(266637,329291,"FY2024","Options:Curr=JPY,Mag=Standard,ConvMethod=R,FilingVer=Current/Restated") -> #NAME? | J4: =SPGLabel(266637,329291,"FY0","Options:Curr=JPY,Mag=Standard,ConvMethod=R,FilingVer=Current/Restated") -> #NAME? | K4: =SPGLabel(266637,290546,"FY+1","Options:Curr=JPY,Mag=Standard,ConvMethod=R,FilingVer=Current/Restated") -> #NAME? | L4: =SPGLabel(266637,290546,"FY+2","Options:Curr=JPY,Mag=Standard,ConvMethod=R,FilingVer=Current/Restated") -> #NAME? | M4: =SPGLabel(266637,272591,"FY2021","Options:Curr=JPY,Mag=Standard,ConvMethod=R,FilingVer=Current/Restated") -> #NAME? | N4: =SPGLabel(266637,272591,"FY2022","Options:Curr=JPY,Mag=Standard,ConvMethod=R,FilingVer=Current/Restated") -> #NAME? | O4: =SPGLabel(266637,272591,"FY2023","Options:Curr=JPY,Mag=Standard,ConvMethod=R,FilingVer=Current/Restated") -> #NAME? | P4: =SPGLabel(266637,272591,"FY2024","Options:Curr=JPY,Mag=Standard,ConvMethod=R,FilingVer=Current/Restated") -> #NAME? | Q4: =SPGLabel(266637,272591,"FY0","Options:Curr=JPY,Mag=Standard,ConvMethod=R,FilingVer=Current/Restated") -> #NAME? | R4: =SPGLabel(266637,272601,"FY2021","Options:Curr=JPY,Mag=Standard,ConvMethod=R,FilingVer=Current/Restated") -> #NAME? | S4: =SPGLabel(266637,272601,"FY2022","Options:Curr=JPY,Mag=Standard,ConvMethod=R,FilingVer=Current/Restated") -> #NAME? | T4: =SPGLabel(266637,272601,"FY2023","Options:Curr=JPY,Mag=Standard,ConvMethod=R,FilingVer=Current/Restated") -> #NAME? | U4: =SPGLabel(266637,272601,"FY2024","Options:Curr=JPY,Mag=Standard,ConvMethod=R,FilingVer=Current/Restated") -> #NAME? | V4: =SPGLabel(266637,272601,"FY0","Options:Curr=JPY,Mag=Standard,ConvMethod=R,FilingVer=Current/Restated") -> #NAME? | W4: =SPGLabel(266637,329316,"FY2021","Options:Curr=JPY,Mag=Standard,ConvMethod=R,FilingVer=Current/Restated") -> #NAME? | X4: =SPGLabel(266637,329316,"FY2022","Options:Curr=JPY,Mag=Standard,ConvMethod=R,FilingVer=Current/Restated") -> #NAME? | Y4: =SPGLabel(266637,329316,"FY2023","Options:Curr=JPY,Mag=Standard,ConvMethod=R,FilingVer=Current/Restated") -> #NAME? | Z4: =SPGLabel(266637,329316,"FY2024","Options:Curr=JPY,Mag=Standard,ConvMethod=R,FilingVer=Current/Restated") -> #NAME? | AA4: =SPGLabel(266637,329316,"FY0","Options:Curr=JPY,Mag=Standard,ConvMethod=R,FilingVer=Current/Restated") -> #NAME? | AB4: =SPGLabel(266637,271442,"","Options:Curr=JPY,Mag=Standard,ConvMethod=R,FilingVer=Current/Restated") -> #NAME? | AC4: =SPGLabel(266637,371494,"LTM","Options:Curr=JPY,Mag=Standard,ConvMethod=R,FilingVer=Current/Restated") -> #NAME? | AD4: =SPGLabel(266637,371493,"LTM","Options:Curr=JPY,Mag=Standard,ConvMethod=R,FilingVer=Current/Restated") -> #NAME? | AE4: =SPGLabel(266637,271669,"","Options:Curr=JPY,Mag=Standard,ConvMethod=R,FilingVer=Current/Restated") -> #NAME? | AF4: =SPGLabel(266637,329068,"","Options:Curr=JPY,Mag=Standard,ConvMethod=R,FilingVer=Current/Restated") -> #NAME?
A5: SP_ENTITY_NAME | B5: SP_ENTITY_ID | C5: SP_NATIVE_COMPANY_NAME | D5: MI_PRIMARY_INDUSTRY | E5: SP_SHARES_OUT | F5: IQ_EBIT | G5: IQ_EBIT | H5: IQ_EBIT | I5: IQ_EBIT | J5: IQ_EBIT | K5: SP_EBIT_EST | L5: SP_EBIT_EST | M5: IQ_CASH_OPER | N5: IQ_CASH_OPER | O5: IQ_CASH_OPER | P5: IQ_CASH_OPER | Q5: IQ_CASH_OPER | R5: IQ_CASH_INVEST | S5: IQ_CASH_INVEST | T5: IQ_CASH_INVEST | U5: IQ_CASH_INVEST | V5: IQ_CASH_INVEST | W5: IQ_ROE | X5: IQ_ROE | Y5: IQ_ROE | Z5: IQ_ROE | AA5: IQ_ROE | AB5: SP_TICKER | AC5: IQ_PE | AD5: IQ_PBV_X | AE5: SP_EXCHANGE | AF5: IQ_INDUSTRY_GROUP
E6: =SPGLabel(266637,329044,"<>11/06/2025","Options:Curr=JPY,Mag=Standard,ConvMethod=R,FilingVer=Current/Restated") -> #NAME? | F6: FY2021 | G6: FY2022 | H6: FY2023 | I6: FY2024 | J6: FY0 | K6: FY+1 | L6: FY+2 | M6: FY2021 | N6: FY2022 | O6: FY2023 | P6: FY2024 | Q6: FY0 | R6: FY2021 | S6: FY2022 | T6: FY2023 | U6: FY2024 | V6: FY0 | W6: FY2021 | X6: FY2022 | Y6: FY2023 | Z6: FY2024 | AA6: FY0 | AC6: LTM | AD6: LTM
A8: &Do Holdings Co.,Ltd. (TSE:3457) | B8: 4984797 | C8: 株式会社Ａｎｄ Ｄｏホールディングス | D8: Homebuilding Producers | E8: 19957406 | F8: 2589 | G8: 2872 | H8: 3177 | I8: 3588 | J8: 2621 | K8: NA | L8: NA | M8: 12696 | N8: 11983 | O8: -12713 | P8: 7440 | Q8: 7522 | R8: -15289 | S8: -20879 | T8: -6408 | U8: -1309 | V8: -735 | W8: 13.216 | X8: 14.629 | Y8: 15.011 | Z8: 15.17 | AA8: 13.114 | AB8: 3457 | AC8: 8.885326 | AD8: 1.13884 | AE8: TSE | AF8: Consumer Durables and Apparel
A9: 3-D Matrix, Ltd. (TSE:7777) | B9: 4813042 | C9: 株式会社スリー・ディー・マトリックス | D9: Biotechnology | E9: 114260900 | F9: -2649 | G9: -2736 | H9: -3158 | I9: -2117 | J9: -1156 | K9: NA | L9: NA | M9: -3249 | N9: -2903 | O9: -4585 | P9: -1899 | Q9: -1714 | R9: -160 | S9: -79 | T9: -81 | U9: -29 | V9: -33 | W9: -188.654 | X9: -121.488 | Y9: -246.72 | Z9: -58.153 | AA9: -194.782 | AB9: 7777 | AC9: NM | AD9: 13.560043 | AE9: TSE | AF9: Pharmaceuticals, Biotechnology and Life Sciences
A10: 4Cs HD Co., Ltd. (TSE:3726) | B10: 4914111 | C10: 株式会社フォーシーズＨＤ | D10: Other Specialty Retail | E10: 10747248 | F10: -148 | G10: -119 | H10: -215 | I10: -126 | J10: -126 | K10: NA | L10: NA | M10: -106 | N10: -41 | O10: -324 | P10: -361 | Q10: -361 | R10: -8 | S10: -4 | T10: -102 | U10: -50 | V10: -50 | W10: -28.098 | X10: -29.799 | Y10: -56.082 | Z10: -32.327 | AA10: -32.327 | AB10: 3726 | AC10: NM | AD10: 3.52574 | AE10: TSE | AF10: Consumer Discretionary Distribution and Retail
A11: A&A Material Corporation (TSE:5391) | B11: 6333703 | C11: 株式会社エーアンドエーマテリアル | D11: Building Products | E11: 7675364 | F11: 1472 | G11: 1441 | H11: 1491 | I11: 2320 | J11: 1917 | K11: NA | L11: NA | M11: 1076 | N11: 1741 | O11: -694 | P11: 3065 | Q11: 1230 | R11: -1215 | S11: -1654 | T11: -317 | U11: 515 | V11: -2624 | W11: 4.958 | X11: 6.227 | Y11: 5.787 | Z11: 15.235 | AA11: -0.639 | AB11: 5391 | AC11: 90.576797 | AD11: 0.493318 | AE11: TSE | AF11: Capital Goods
A12: A&D HOLON Holdings Company, Limited (TSE:7745) | B12: 4298464 | C12: 株式会社Ａ＆Ｄホロンホールディングス | D12: Electronic Equipment and Instruments | E12: 27373761 | F12: 4405 | G12: 5497 | H12: 7476 | I12: 7956 | J12: 8813 | K12: 9422.5 | L12: 9890 | M12: 5194 | N12: 1782 | O12: 4096 | P12: 7201 | Q12: 6578 | R12: -2222 | S12: -2395 | T12: -1364 | U12: -2007 | V12: -2005 | W12: 17.082 | X12: 15.761 | Y12: 18.576 | Z12: 15.125 | AA12: 16.12 | AB12: 7745 | AC12: 8.355675 | AD12: 1.210617 | AE12: TSE | AF12: Technology Hardware and Equipment
A13: A.D.Works Group Co.,Ltd. (TSE:2982) | B13: 19462280 | C13: 株式会社ＡＤワークスグループ | D13: Real Estate Services | E13: 48530334 | F13: 927 | G13: 1370 | H13: 2435 | I13: 3209 | J13: 3209 | K13: NA | L13: NA | M13: -4435 | N13: -11454 | O13: -683 | P13: 1725 | Q13: 1725 | R13: -151 | S13: 142 | T13: -146 | U13: -329 | V13: -329 | W13: 2.233 | X13: 3.541 | Y13: 8.595 | Z13: 8.936 | AA13: 8.936 | AB13: 2982 | AC13: 9.91753 | AD13: 1.149741 | AE13: TSE | AF13: Real Estate Management and Development
A14: AB&Company Co.,Ltd. (TSE:9251) | B14: 11097415 | C14: 株式会社AB&Company | D14: Specialized Consumer Services | E14: 14246059 | F14: 1526 | G14: 1368 | H14: 1852 | I14: 1679 | J14: 1679 | K14: 1750 | L14: 1850 | M14: 2198 | N14: 2278 | O14: 2714 | P14: 3411 | Q14: 3411 | R14: -426 | S14: -693 | T14: -637 | U14: -700 | V14: -700 | W14: 14.546 | X14: 11.178 | Y14: 13.476 | Z14: 12.654 | AA14: 12.654 | AB14: 9251 | AC14: 15.044273 | AD14: 1.707736 | AE14: TSE | AF14: Consumer Services
A15: Abalance Corporation (TSE:3856) | B15: 4972437 | C15: Ａｂａｌａｎｃｅ株式会社 | D15: Semiconductors | E15: 18903017 | F15: 1362 | G15: 1581 | H15: 12805 | I15: 23268 | J15: 4817.332 | K15: NA | L15: NA | M15: -608 | N15: -6449 | O15: 18526 | P15: 44757 | Q15: -13814.663 | R15: -1391 | S15: -13221 | T15: -20670 | U15: -21191 | V15: -3493.332 | W15: 26.849 | X15: 24.479 | Y15: 77.665 | Z15: 61.972 | AA15: NA | AB15: 3856 | AC15: 14.102888 | AD15: 0.731827 | AE15: TSE | AF15: Semiconductors and Semiconductor Equipment
A16: abc Co., Ltd. (TSE:8783) | B16: 4773566 | C16: ａｂｃ株式会社 | D16: Restaurants | E16: 28912248 | F16: -1465 | G16: -699 | H16: -1914 | I16: -2116 | J16: -2615 | K16: NA | L16: NA | M16: 41 | N16: -965 | O16: -3314 | P16: -1472 | Q16: -2420 | R16: -205 | S16: -235 | T16: -895 | U16: -625 | V16: -3425 | W16: -219.727 | X16: -449.711 | Y16: -256.254 | Z16: -328.963 | AA16: -292.747 | AB16: 8783 | AC16: NM | AD16: 2.200081 | AE16: TSE | AF16: Consumer Services
A17: ABC-Mart,Inc. (TSE:2670) | B17: 4916142 | C17: 株式会社エービーシー・マート | D17: Apparel Retail | E17: 247616642 | F17: 19515 | G17: 27448 | H17: 42302 | I17: 55672 | J17: 62551 | K17: 64822.018 | L17: 67487.047 | M17: 23487 | N17: 25157 | O17: 10882 | P17: 51230 | Q17: 56125 | R17: -11316 | S17: -7458 | T17: -9003 | U17: -11405 | V17: -15103 | W17: 7.039 | X17: 6.198 | Y17: 10.207 | Z17: 12.303 | AA17: 12.782 | AB17: 2670 | AC17: 14.516901 | AD17: 1.738265 | AE17: TSE | AF17: Consumer Discretionary Distribution and Retail
A18: ABEJA, Inc. (TSE:5574) | B18: 5267033 | C18: 株式会社ABEJA | D18: Application Software | E18: 9405600 | F18: -265 | G18: -163 | H18: 403 | I18: 291 | J18: 446 | K18: 480 | L18: 599 | M18: NA | N18: NA | O18: 460 | P18: -760 | Q18: 1621 | R18: NA | S18: NA | T18: -5 | U18: -28 | V18: -28 | W18: NA | X18: -10.376 | Y18: 15.968 | Z18: 5.91 | AA18: 10.707 | AB18: 5574 | AC18: 63.356481 | AD18: 5.972748 | AE18: TSE | AF18: Software and Services
A19: Abhotel Co., Ltd. (TSE:6565) | B19: 6567493 | C19: ＡＢホテル株式会社 | D19: Hotels, Resorts and Cruise Lines | E19: 14175573 | F19: 45 | G19: 959 | H19: 2977 | I19: 3612 | J19: 3963 | K19: NA | L19: NA | M19: -10 | N19: 2056 | O19: 2996 | P19: 2842 | Q19: 3277 | R19: -2065 | S19: -516 | T19: -194 | U19: -1161 | V19: -3778 | W19: 0.166 | X19: 9.052 | Y19: 24.368 | Z19: 24.696 | AA19: 21.931 | AB19: 6565 | AC19: 8.535277 | AD19: 1.737771 | AE19: TSE | AF19: Consumer Services
A20: ABIST Co.,Ltd. (TSE:6087) | B20: 4996292 | C20: 株式会社アビスト | D20: Research and Consulting Services | E20: 3979320 | F20: 429 | G20: 735 | H20: 717.967 | I20: 903.484 | J20: 903.484 | K20: NA | L20: NA | M20: 341 | N20: 711 | O20: 827.91 | P20: 572.35 | Q20: 572.35 | R20: 638 | S20: -44 | T20: 40.86 | U20: 12.136 | V20: 12.136 | W20: 9.361 | X20: 4.92 | Y20: 11.308 | Z20: 9.007 | AA20: 9.007 | AB20: 6087 | AC20: 21.503975 | AD20: 1.817074 | AE20: TSE | AF20: Commercial and Professional Services
A21: Accelia, Inc. (TSE:271A) | B21: 6477405 | D21: Alternative Carriers | E21: 834000 | F21: NA | G21: NA | H21: 12 | I21: 30 | J21: 1 | K21: NA | L21: NA | M21: NA | N21: NA | O21: NA | P21: NA | Q21: -33 | R21: NA | S21: NA | T21: NA | U21: NA | V21: -31 | W21: NA | X21: NA | Y21: NA | Z21: 4.054 | AA21: 0 | AB21: 271A | AC21: NM | AD21: NA | AE21: TSE | AF21: Telecommunication Services
A22: Access Co., Ltd. (TSE:4813) | B22: 4207883 | C22: 株式会社ＡＣＣＥＳＳ | D22: Application Software | E22: 37787430 | F22: -2120 | G22: -3207 | H22: -1510 | I22: -1978 | J22: -2260 | K22: NA | L22: NA | M22: 302 | N22: -370 | O22: -909 | P22: 96 | Q22: 1134 | R22: -2621 | S22: -1335 | T22: -1056 | U22: -1571 | V22: -1068 | W22: -8.576 | X22: -14.75 | Y22: -13.174 | Z22: -13.967 | AA22: -42.77 | AB22: 4813 | AC22: NM | AD22: 2.756604 | AE22: TSE | AF22: Software and Services
A23: Access Group Holdings Co., Ltd. (TSE:7042) | B23: 6840415 | C23: 株式会社アクセスグループ・ホールディングス | D23: Advertising | E23: 3210410 | F23: -226 | G23: 55 | H23: 181 | I23: 89 | J23: 230 | K23: NA | L23: NA | M23: -436 | N23: -20 | O23: -138 | P23: 244 | Q23: 190 | R23: 56 | S23: 269 | T23: 216 | U23: 22 | V23: 43 | W23: -66.667 | X23: 2.483 | Y23: NA | Z23: 18.829 | AA23: 18.477 | AB23: 7042 | AC23: 12.227212 | AD23: 1.624926 | AE23: TSE | AF23: Media and Entertainment
A24: Accrete Inc. (TSE:4395) | B24: 7709174 | C24: 株式会社アクリート | D24: Wireless Telecommunication Services | E24: 6769884 | F24: 466 | G24: 1172 | H24: 310 | I24: 331 | J24: 331 | K24: NA | L24: NA | M24: 359 | N24: 976 | O24: 191 | P24: 214 | Q24: 214 | R24: -464 | S24: -471 | T24: -95 | U24: -104 | V24: -104 | W24: NA | X24: 43.542 | Y24: -1.157 | Z24: -5.196 | AA24: -5.196 | AB24: 4395 | AC24: 41.268729 | AD24: 2.526438 | AE24: TSE | AF24: Telecommunication Services
A25: Achilles Corporation (TSE:5142) | B25: 4986666 | C25: アキレス株式会社 | D25: Commodity Chemicals | E25: 13666949 | F25: 1571 | G25: 856 | H25: -712 | I25: -959 | J25: -436 | K25: NA | L25: NA | M25: 4509 | N25: 4707 | O25: -1072 | P25: 1878 | Q25: 2686 | R25: -2830 | S25: -5030 | T25: -4484 | U25: -3793 | V25: -1918 | W25: 7.329 | X25: 3.241 | Y25: -2.564 | Z25: -19.148 | AA25: 1.083 | AB25: 5142 | AC25: 22.887734 | AD25: 0.416417 | AE25: TSE | AF25: Materials
A26: Acmos Inc. (TSE:6888) | B26: 4545341 | C26: アクモス株式会社 | D26: Application Software | E26: 9948057 | F26: 501 | G26: 472 | H26: 650 | I26: 661 | J26: 584 | K26: NA | L26: NA | M26: 290 | N26: 358 | O26: 626 | P26: 347 | Q26: 256 | R26: -26 | S26: -341 | T26: -118 | U26: -230 | V26: -13 | W26: 15.967 | X26: 11.688 | Y26: 14.917 | Z26: 13.529 | AA26: 11.37 | AB26: 6888 | AC26: 14.735021 | AD26: 1.70871 | AE26: TSE | AF26: Software and Services
A27: Acom Co., Ltd. (TSE:8572) | B27: 4250356 | C27: アコム株式会社 | D27: Specialty Finance: Consumer Focused | E27: 1566613978 | F27: 98897 | G27: 34779 | H27: 91303 | I27: 91280 | J27: 64314 | K27: 95288.378 | L27: 100760.05 | M27: 113179 | N27: 46089 | O27: -1318 | P27: -36759 | Q27: 876 | R27: -4566 | S27: -4032 | T27: -2692 | U27: -6178 | V27: -6478 | W27: 17.469 | X27: 11.085 | Y27: 10.048 | Z27: 8.937 | AA27: 5.288 | AB27: 8572 | AC27: 13.349016 | AD27: 1.049313 | AE27: TSE | AF27: Financial Services
A28: ACSL Ltd. (TSE:6232) | B28: 6322700 | C28: 株式会社ＡＣＳＬ | D28: Electronic Equipment and Instruments | E28: 15924439 | F28: -1585.333 | G28: -2203 | H28: -2071 | I28: -2293 | J28: -2293 | K28: -1400 | L28: -700 | M28: -1793.333 | N28: -2148 | O28: -2572 | P28: -1902 | Q28: -1902 | R28: -1001.333 | S28: -271 | T28: -94 | U28: -46 | V28: -46 | W28: NA | X28: -62.062 | Y28: -97.865 | Z28: -193.078 | AA28: -193.078 | AB28: 6232 | AC28: NM | AD28: 29.037746 | AE28: TSE | AF28: Technology Hardware and Equipment
A29: ACTBE Inc. (TSE:439A) | B29: 113256625 | D29: IT Consulting and Other Services | E29: 100000 | F29: NA | G29: NA | H29: NA | I29: NA | J29: 35 | K29: NA | L29: NA | M29: NA | N29: NA | O29: NA | P29: NA | Q29: NA | R29: NA | S29: NA | T29: NA | U29: NA | V29: NA | W29: NA | X29: NA | Y29: NA | Z29: NA | AA29: NA | AB29: 439A | AC29: 23.809524 | AD29: NA | AE29: TSE | AF29: Software and Services
A30: Adeka Corporation (TSE:4401) | B30: 6354598 | C30: 株式会社ＡＤＥＫＡ | D30: Commodity Chemicals | E30: 100330297 | F30: 28980 | G30: 34928 | H30: 32371 | I30: 35429 | J30: 41011 | K30: 42757.143 | L30: 46257.143 | M30: 36872 | N30: 21367 | O30: 17253 | P30: 41954 | Q30: 46235 | R30: -14189 | S30: -11317 | T30: -19520 | U30: -23069 | V30: -12553 | W30: 7.447 | X30: 9.629 | Y30: 6.888 | Z30: 8.078 | AA30: 8.248 | AB30: 4401 | AC30: 14.138828 | AD30: 1.196395 | AE30: TSE | AF30: Materials
A31: adish Co., Ltd. (TSE:7093) | B31: 9831689 | C31: アディッシュ株式会社 | D31: Internet Services and Infrastructure | E31: 1964560 | F31: 52 | G31: 98 | H31: -172 | I31: -132 | J31: -132 | K31: NA | L31: NA | M31: 112 | N31: 93 | O31: -249 | P31: -186 | Q31: -186 | R31: -55 | S31: -15 | T31: -14 | U31: -16 | V31: -16 | W31: 7.799 | X31: 11.241 | Y31: -33.333 | Z31: -29.151 | AA31: -29.151 | AB31: 7093 | AC31: NM | AD31: 2.796235 | AE31: TSE | AF31: Software and Services
A32: Adjuvant Holdings Co.,Ltd. (TSE:4929) | B32: 4916932 | C32: 株式会社アジュバンホールディングス | D32: Personal Care and Beauty Products: Producers | E32: 8000395 | F32: 294 | G32: 391 | H32: 233 | I32: -1 | J32: 127 | K32: NA | L32: NA | M32: 403 | N32: 417 | O32: -321 | P32: 377 | Q32: 307 | R32: -235 | S32: 24 | T32: 344 | U32: 391 | V32: -95 | W32: 3.457 | X32: 9.347 | Y32: 9.155 | Z32: -2.275 | AA32: 0.953 | AB32: 4929 | AC32: 164.17587 | AD32: 1.481988 | AE32: TSE | AF32: Household and Personal Products
A33: ADR120S, Inc. (TSE:3750) | B33: 4989711 | C33: 株式会社ＡＤＲ１２０Ｓ | D33: Diversified Real Estate Activities | E33: 8928219 | F33: -731 | G33: -462 | H33: -795 | I33: -773 | J33: -807 | K33: NA | L33: NA | M33: -82 | N33: -187 | O33: -39 | P33: -1152 | Q33: -987 | R33: 6 | S33: -216 | T33: -283 | U33: 8689 | V33: 22 | W33: -21.008 | X33: -2.121 | Y33: -33.244 | Z33: 5.064 | AA33: -125 | AB33: 3750 | AC33: NM | AD33: 15.331699 | AE33: TSE | AF33: Real Estate Management and Development
A34: Ad-Sol Nissin Corporation (TSE:3837) | B34: 4970320 | C34: アドソル日進株式会社 | D34: IT Consulting and Other Services | E34: 17459596 | F34: 1285 | G34: 1088 | H34: 1211 | I34: 1438 | J34: 1711 | K34: 1900 | L34: 2100 | M34: 187 | N34: 1781 | O34: 1020 | P34: 804 | Q34: 1027 | R34: -6 | S34: -241 | T34: -99 | U34: -71 | V34: -202 | W34: NA | X34: 13.88 | Y34: 13.305 | Z34: 14.022 | AA34: 16.836 | AB34: 3837 | AC34: 18.880746 | AD34: 3.226916 | AE34: TSE | AF34: Software and Services
A35: Adtec Plasma Technology Co., Ltd. (TSE:6668) | B35: 4545709 | C35: 株式会社アドテック プラズマ テクノロジー | D35: Electronic Equipment and Instruments | E35: 8567267 | F35: 1103 | G35: 2736 | H35: 2242 | I35: 1486 | J35: 1809 | K35: NA | L35: NA | M35: -185 | N35: -1583 | O35: -1501 | P35: 3032 | Q35: 3364 | R35: -226 | S35: -1709 | T35: -1935 | U35: -937 | V35: -259 | W35: 13.851 | X35: 27.455 | Y35: 16.782 | Z35: 10.565 | AA35: 15.881 | AB35: 6668 | AC35: 5.251886 | AD35: 0.800175 | AE35: TSE | AF35: Technology Hardware and Equipment
A36: Advan Group Co., Ltd. (TSE:7463) | B36: 4993150 | C36: 株式会社アドヴァングループ | D36: Trading Companies and Distributors | E36: 34101145 | F36: 4086 | G36: 3828 | H36: 4702 | I36: 3939 | J36: 3151 | K36: NA | L36: NA | M36: 5457 | N36: 3209 | O36: 3753 | P36: 4967 | Q36: 1890 | R36: -4676 | S36: -506 | T36: -8091 | U36: -5582 | V36: 1186 | W36: 6.667 | X36: 9.162 | Y36: 7.914 | Z36: 22.404 | AA36: 11.623 | AB36: 7463 | AC36: 4.071104 | AD36: 0.543924 | AE36: TSE | AF36: Capital Goods
A37: Advance Create Co., Ltd. (TSE:8798) | B37: 5000326 | C37: 株式会社アドバンスクリエイト | D37: Insurance Broker | E37: 31896771 | F37: 891 | G37: 95 | H37: -1303 | I37: -712 | J37: -712 | K37: NA | L37: NA | M37: 1643 | N37: 364 | O37: -206 | P37: -1674 | Q37: -1674 | R37: -485 | S37: -391 | T37: -668 | U37: -117 | V37: -117 | W37: 3.757 | X37: -65.599 | Y37: 325.267 | Z37: 61.61 | AA37: 61.61 | AB37: 8798 | AC37: NM | AD37: NM | AE37: TSE | AF37: Insurance
A38: Advanced Media, Inc. (TSE:3773) | B38: 4970714 | C38: 株式会社アドバンスト・メディア | D38: Application Software | E38: 15600391 | F38: 680 | G38: 812 | H38: 1081 | I38: 1359 | J38: 1443 | K38: 1290 | L38: 1320 | M38: 1232 | N38: 1149 | O38: 1266 | P38: 1494 | Q38: 1432 | R38: -402 | S38: -367 | T38: -2861 | U38: -1270 | V38: -1069 | W38: 5.666 | X38: 3.855 | Y38: 8.093 | Z38: 9.588 | AA38: 11.95 | AB38: 3773 | AC38: 10.877955 | AD38: 1.281781 | AE38: TSE | AF38: Software and Services
A39: Advanex Inc. (TSE:5998) | B39: 4992625 | C39: 株式会社アドバネクス | D39: Machinery and Supplies and Components: Industrial | E39: 4105745 | F39: 176 | G39: 148 | H39: 61 | I39: 387 | J39: 1109 | K39: 1400 | L39: 1700 | M39: 1404 | N39: 945 | O39: 279 | P39: 2048 | Q39: 509 | R39: 327 | S39: -1557 | T39: -1599 | U39: -667 | V39: -1302 | W39: 11.182 | X39: -1.238 | Y39: 0.849 | Z39: 3.456 | AA39: -7.668 | AB39: 5998 | AC39: NM | AD39: 0.823195 | AE39: TSE | AF39: Capital Goods
A40: Advantage Risk Management Co., Ltd. (TSE:8769) | B40: 4812978 | C40: 株式会社アドバンテッジリスクマネジメント | D40: Health Care Services | E40: 15697546 | F40: 727 | G40: 353 | H40: 553 | I40: 726 | J40: 1023 | K40: NA | L40: NA | M40: 712 | N40: 578 | O40: 931 | P40: 1292 | Q40: 1705 | R40: -772 | S40: -2148 | T40: -219 | U40: -948 | V40: -2262 | W40: 14.041 | X40: 5.648 | Y40: 10.674 | Z40: 13.256 | AA40: 18.743 | AB40: 8769 | AC40: 13.349683 | AD40: 2.663615 | AE40: TSE | AF40: Health Care Equipment and Services
A41: Advantest Corporation (TSE:6857) | B41: 4228826 | C41: 株式会社アドバンテスト | D41: Semiconductor Materials and Equipment | E41: 727392176 | F41: 68275 | G41: 114734 | H41: 167687 | I41: 90626 | J41: 249554 | K41: 360320.72 | L41: 415033.71 | M41: 67830 | N41: 78889 | O41: 70224 | P41: 32668 | Q41: 285971 | R41: -16831 | S41: -46907 | T41: -26706 | U41: -27940 | V41: -42189 | W41: 27.27 | X41: 30.366 | Y41: 39.318 | Z41: 15.575 | AA41: 34.376 | AB41: 6857 | AC41: 56.133483 | AD41: 23.787958 | AE41: TSE | AF41: Semiconductors and Semiconductor Equipment
A42: Adventure, Inc. (TSE:6030) | B42: 4980613 | C42: 株式会社アドベンチャー | D42: Hotels, Resorts and Cruise Lines | E42: 7435578 | F42: 820 | G42: 1983 | H42: 2881 | I42: 1589 | J42: 1085 | K42: NA | L42: NA | M42: -251 | N42: 2999 | O42: 3040 | P42: 856 | Q42: 2220 | R42: -628 | S42: 351 | T42: -895 | U42: -295 | V42: -1139 | W42: 39.43 | X42: 22.366 | Y42: 17.406 | Z42: 5.93 | AA42: -19.364 | AB42: 6030 | AC42: NM | AD42: 1.871203 | AE42: TSE | AF42: Consumer Services
A43: Adways Inc. (TSE:2489) | B43: 4993415 | C43: 株式会社アドウェイズ | D43: Advertising | E43: 39082120 | F43: 1842 | G43: 1183 | H43: 922 | I43: 159 | J43: 159 | K43: NA | L43: NA | M43: 1232 | N43: 385 | O43: 592 | P43: 185 | Q43: 185 | R43: -289.333 | S43: 1957 | T43: -95 | U43: 155 | V43: 155 | W43: NA | X43: 16.592 | Y43: 5.97 | Z43: -3.083 | AA43: -3.083 | AB43: 2489 | AC43: NM | AD43: 0.860196 | AE43: TSE | AF43: Media and Entertainment
...
